Workbook
Name NativeTimeline_Order_date1: #N/A
Name Slicer_Loyalty_cards: #N/A
Name Slicer_Loyalty_cards1: #N/A
Name Slicer_Roast_type: #N/A
Name Slicer_Roast_type1: #N/A
Name Slicer_Size: #N/A
Name Slicer_Size1: #N/A

Sheet Customers
A1: Customer ID | B1: Customer Name | C1: Email | D1: Phone Number | E1: Address | F1: City | G1: Country | H1: Postcode | I1: Loyalty Card
A2: CUST001 | B2: Jennifer Rodriguez | C2: tiffany38@hernandez-palmer.com | D2: 736-814-8127x615 | E2: Christopher Bridge | F2: Taylorfurt | G2: Uruguay | H2: 64585 | I2: No
A3: CUST002 | B3: Amanda Rhodes | C3: joycemariah@forbes-velasquez.com | D3: +1-998-018-6546x338 | E3: Greene Green | F3: Atkinsland | G3: Cayman Islands | H3: 89348 | I3: Yes
A4: CUST003 | B4: Carolyn Howard | C4: scott42@thompson-friedman.org | D4: 519.531.2027x238 | E4: Dawn Shoals | F4: North Loriport | G4: Montserrat | H4: 81842 | I4: Yes
A5: CUST004 | B5: Jessica Young | C5: ryan79@hotmail.com | D5: +1-059-620-1168 | E5: Matthew Loaf | F5: =VLOOKUP(Customers!A19,Customers!$A$1:$I$21,2,0) -> Jeffrey Moore | G5: Saint Vincent and the Grenadines | H5: 68186 | I5: No
A6: CUST005 | B6: Joshua Oneal | C6: hestercharles@jackson-hicks.com | D6: 001-196-985-6506 | E6: Cooper Throughway | F6: Erikshire | G6: Cook Islands | H6: 10641 | I6: Yes
A7: CUST006 | B7: Jane Taylor | C7: egould@navarro.biz | D7: +1-659-964-9852x721 | E7: Wade Curve | F7: East Laurenmouth | G7: Tuvalu | H7: 43814 | I7: No
A8: CUST007 | B8: Dustin Levy | C8: plamb@thomas.com | D8: +1-255-904-5555x0820 | E8: Wilson Trafficway | F8: East Martin | G8: Bhutan | H8: 36128 | I8: Yes
A9: CUST008 | B9: Sarah Johnson | C9: tedwards@collins.com | D9: 509.913.0612x4886 | E9: Mary Wells | F9: New Elizabethmouth | G9: Dominican Republic | H9: 96344 | I9: Yes
A10: CUST009 | B10: Ashley Guerrero | C10: clementscole@stewart.com | D10: 294.822.5865 | E10: Heather Motorway | F10: South Robert | G10: Congo | H10: 69620 | I10: No
A11: CUST010 | B11: Robin Johnson | C11: rvillanueva@hotmail.com | D11: (661)768-9188 | E11: Heather Meadows | F11: South Ryan | G11: Greenland | H11: 06368 | I11: Yes
A12: CUST011 | B12: Andrew Patton | C12: mcphersonashley@lynn.com | D12: 0078469677 | E12: Shane Port | F12: Clayville | G12: Western Sahara | H12: 08563 | I12: Yes
A13: CUST012 | B13: Billy Chan | C13: jonathandavis@yahoo.com | D13: 012.184.9762 | E13: Fisher Shore | F13: Port Lisashire | G13: Turks and Caicos Islands | H13: 56246 | I13: No
A14: CUST013 | B14: Kenneth Mcfarland | C14: gregory16@murphy.com | D14: 146-626-8659x449 | E14: Lee Hill | F14: North Lukeport | G14: Zambia | H14: 58984 | I14: Yes
A15: CUST014 | B15: Timothy Anderson | C15: ucunningham@webb.com | D15: 001-532-154-8326x7800 | E15: Caleb Common | F15: Christianberg | G15: Montenegro | H15: 28376 | I15: No
A16: CUST015 | B16: Teresa Collins | C16: carsonkenneth@hotmail.com | D16: 001-523-678-5349 | E16: Roberts Camp | F16: West Elizabeth | G16: Anguilla | H16: 80229 | I16: Yes
A17: CUST016 | B17: Megan Rice | C17: bakerjuan@hotmail.com | D17: (461)547-3573 | E17: Herrera Stravenue | F17: Port Joshuaport | G17: Moldova | H17: 70897 | I17: Yes
... A21: CUST020 | B21: Natalie Cox | C21: cervantesgabriela@morgan.net | D21: 078.132.3750x9284 | E21: Steven Crest | F21: New Kim | G21: Northern Mariana Islands | H21: 51241 | I21: No

Sheet Sheet2
A3: customer name | B3: Sum of Sales | T3: refresh
A4: Jennifer Rodriguez | B4: 64.72
A5: Dustin Levy | B5: 77.36
A6: Timothy Anderson | B6: 117.91
A7: Joshua Oneal | B7: 118.13
A8: Natalie Cox | B8: 150.4

Sheet Sheet4

Sheet Sheet3

Sheet Sheet5
A3: Sum of Sales | B3: Column Labels
A4: Row Labels | B4: Americano | C4: Cappuccino | D4: Espresso | E4: Flat White | F4: Latte | G4: Mocha | H4: Grand Total
A5: 2024
A6: Jun | E6: 28.2 | G6: 57.36 | H6: 85.56
A7: Jul | B7: 28.92 | D7: 51.37 | E7: 24.88 | F7: 56.68 | G7: 9.6 | H7: 171.45
A8: Aug | B8: 39.33 | D8: 28.17 | E8: 21.16 | H8: 88.66
A9: Oct | B9: 5.4 | G9: 47.4 | H9: 52.8
A10: Nov | F10: 45 | G10: 13.25 | H10: 58.25
A11: Dec | F11: 30 | H11: 30
A12: 2025
A13: Jan | D13: 49.67 | F13: 31.14 | G13: 42.84 | H13: 123.65
A14: Feb | B14: 14.46 | C14: 35.36 | D14: 3.13 | E14: 29.16 | G14: 54.4 | H14: 136.51
A15: Mar | B15: 48.2 | G15: 5.5 | H15: 53.7
A16: Apr | C16: 35.36 | E16: 27.99 | F16: 11.22 | H16: 74.57
A17: May | D17: 38.97 | H17: 38.97
A18: Grand Total | B18: 136.31 | C18: 70.72 | D18: 171.31 | E18: 131.39 | F18: 174.04 | G18: 230.35 | H18: 914.12

Sheet Sheet1
A3: Row Labels | B3: Sum of Sales
A4: Anguilla | B4: 44.12
A5: Bhutan | B5: 42
A6: Cayman Islands | B6: 9.6
A7: Congo | B7: 37.9
A8: Cook Islands | B8: 98.36
A9: Greenland | B9: 39.24
A10: Moldova | B10: 33.84
A11: Montenegro | B11: 157.64
A12: Montserrat | B12: 38.4
A13: Namibia | B13: 20.73
A14: Northern Mariana Islands | B14: 150.4
A15: Slovenia | B15: 57.47
... A20: Grand Total | B20: 914.12

Sheet owner
A1: Order ID | B1: Order date | C1: Customer ID | D1: Product ID | E1: Quantity | F1: customer name | G1: Email | H1: Country | I1: Coffee type | J1: Roast type | K1: Size | L1: Unit price | M1: Sales | N1: Loyalty cards
A2: ORD0001 | B2: 45764 | C2: CUST010 | D2: PROD004 | E2: 3 | F2: =VLOOKUP(C2,Customers!A2:B21,2,FALSE) -> Robin Johnson | G2: =INDEX(Customers!C$1:C$21, MATCH(C2, Customers!A$1:A$21, 0)) -> rvillanueva@hotmail.com | H2: =INDEX(Customers!$G$1:$G$21, MATCH(C2,Customers!$A$1:$A$21,0)) -> Greenland | I2: =INDEX(Products!B$2:B$41, MATCH(D2, Products!A$2:A$41, 0)) -> Latte | J2: =INDEX(Products!C$2:C$41, MATCH(D2, Products!A$2:A$41, 0)) -> Dark | K2: =INDEX(Products!D$2:D$41, MATCH(D2, Products!A$2:A$41, 0)) -> Medium | L2: =INDEX(Products!E$2:E$41, MATCH(D2, Products!A$2:A$41, 0)) -> 3.74 | M2: =L2*E2 -> 11.22 | N2: =INDEX(Customers!I$2:I$41, MATCH(C2, Customers!A$2:A$41, 0)) -> Yes
A3: ORD0002 | B3: 45478 | C3: CUST005 | D3: PROD003 | E3: 4 | F3: =VLOOKUP(C3,Customers!A3:B22,2,FALSE) -> Joshua Oneal | G3: =INDEX(Customers!C$1:C$21, MATCH(C3, Customers!A$1:A$21, 0)) -> hestercharles@jackson-hicks.com | H3: =INDEX(Customers!$G$1:$G$21, MATCH(C3,Customers!$A$1:$A$21,0)) -> Cook Islands | I3: =INDEX(Products!B$2:B$41, MATCH(D3, Products!A$2:A$41, 0)) -> Latte | J3: =INDEX(Products!C$2:C$41, MATCH(D3, Products!A$2:A$41, 0)) -> Dark | K3: =INDEX(Products!D$2:D$41, MATCH(D3, Products!A$2:A$41, 0)) -> Large | L3: =INDEX(Products!E$2:E$41, MATCH(D3, Products!A$2:A$41, 0)) -> 5 | M3: =L3*E3 -> 20 | N3: =INDEX(Customers!I$2:I$41, MATCH(C3, Customers!A$2:A$41, 0)) -> Yes
A4: ORD0003 | B4: 45502 | C4: CUST002 | D4: PROD002 | E4: 2 | F4: =VLOOKUP(Customers!A3,Customers!$A$1:$I$21,2,0) -> Amanda Rhodes | G4: =INDEX(Customers!C$1:C$21, MATCH(C4, Customers!A$1:A$21, 0)) -> joycemariah@forbes-velasquez.com | H4: =INDEX(Customers!$G$1:$G$21, MATCH(C4,Customers!$A$1:$A$21,0)) -> Cayman Islands | I4: =INDEX(Products!B$2:B$41, MATCH(D4, Products!A$2:A$41, 0)) -> Mocha | J4: =INDEX(Products!C$2:C$41, MATCH(D4, Products!A$2:A$41, 0)) -> Light | K4: =INDEX(Products!D$2:D$41, MATCH(D4, Products!A$2:A$41, 0)) -> Large | L4: =INDEX(Products!E$2:E$41, MATCH(D4, Products!A$2:A$41, 0)) -> 4.8 | M4: =L4*E4 -> 9.6 | N4: =INDEX(Customers!I$2:I$41, MATCH(C4, Customers!A$2:A$41, 0)) -> Yes
A5: ORD0004 | B5: 45694 | C5: CUST018 | D5: PROD014 | E5: 1 | F5: =VLOOKUP(Customers!A19,Customers!$A$1:$I$21,2,0) -> Jeffrey Moore | G5: =INDEX(Customers!C$1:C$21, MATCH(C5, Customers!A$1:A$21, 0)) -> jessica31@sanchez-young.com | H5: =INDEX(Customers!$G$1:$G$21, MATCH(C5,Customers!$A$1:$A$21,0)) -> Slovenia | I5: =INDEX(Products!B$2:B$41, MATCH(D5, Products!A$2:A$41, 0)) -> Espresso | J5: =INDEX(Products!C$2:C$41, MATCH(D5, Products!A$2:A$41, 0)) -> Light | K5: =INDEX(Products!D$2:D$41, MATCH(D5, Products!A$2:A$41, 0)) -> Small | L5: =INDEX(Products!E$2:E$41, MATCH(D5, Products!A$2:A$41, 0)) -> 3.13 | M5: =L5*E5 -> 3.13 | N5: =INDEX(Customers!I$2:I$41, MATCH(C5, Customers!A$2:A$41, 0)) -> No
A6: ORD0005 | B6: 45760 | C6: CUST007 | D6: PROD009 | E6: 9 | F6: =VLOOKUP(Customers!A8,Customers!$A$1:$I$21,2,0) -> Dustin Levy | G6: =INDEX(Customers!C$1:C$21, MATCH(C6, Customers!A$1:A$21, 0)) -> plamb@thomas.com | H6: =INDEX(Customers!$G$1:$G$21, MATCH(C6,Customers!$A$1:$A$21,0)) -> Bhutan | I6: =INDEX(Products!B$2:B$41, MATCH(D6, Products!A$2:A$41, 0)) -> Flat White | J6: =INDEX(Products!C$2:C$41, MATCH(D6, Products!A$2:A$41, 0)) -> Dark | K6: =INDEX(Products!D$2:D$41, MATCH(D6, Products!A$2:A$41, 0)) -> Small | L6: =INDEX(Products!E$2:E$41, MATCH(D6, Products!A$2:A$41, 0)) -> 3.11 | M6: =L6*E6 -> 27.99 | N6: =INDEX(Customers!I$2:I$41, MATCH(C6, Customers!A$2:A$41, 0)) -> Yes
A7: ORD0006 | B7: 45492 | C7: CUST015 | D7: PROD007 | E7: 8 | F7: =INDEX(Customers!B1:B21, MATCH(C7, Customers!A1:A21, 0)) -> Teresa Collins | G7: =INDEX(Customers!C$1:C$21, MATCH(C7, Customers!A$1:A$21, 0)) -> carsonkenneth@hotmail.com | H7: =INDEX(Customers!$G$1:$G$21, MATCH(C7,Customers!$A$1:$A$21,0)) -> Anguilla | I7: =INDEX(Products!B$2:B$41, MATCH(D7, Products!A$2:A$41, 0)) -> Espresso | J7: =INDEX(Products!C$2:C$41, MATCH(D7, Products!A$2:A$41, 0)) -> Light | K7: =INDEX(Products!D$2:D$41, MATCH(D7, Products!A$2:A$41, 0)) -> Large | L7: =INDEX(Products!E$2:E$41, MATCH(D7, Products!A$2:A$41, 0)) -> 4.67 | M7: =L7*E7 -> 37.36 | N7: =INDEX(Customers!I$2:I$41, MATCH(C7, Customers!A$2:A$41, 0)) -> Yes
A8: ORD0007 | B8: 45488 | C8: CUST007 | D8: PROD007 | E8: 3 | F8: =INDEX(Customers!B2:B22, MATCH(C8, Customers!A2:A22, 0)) -> Dustin Levy | G8: =INDEX(Customers!C$1:C$21, MATCH(C8, Customers!A$1:A$21, 0)) -> plamb@thomas.com | H8: =INDEX(Customers!$G$1:$G$21, MATCH(C8,Customers!$A$1:$A$21,0)) -> Bhutan | I8: =INDEX(Products!B$2:B$41, MATCH(D8, Products!A$2:A$41, 0)) -> Espresso | J8: =INDEX(Products!C$2:C$41, MATCH(D8, Products!A$2:A$41, 0)) -> Light | K8: =INDEX(Products!D$2:D$41, MATCH(D8, Products!A$2:A$41, 0)) -> Large | L8: =INDEX(Products!E$2:E$41, MATCH(D8, Products!A$2:A$41, 0)) -> 4.67 | M8: =L8*E8 -> 14.01 | N8: =INDEX(Customers!I$2:I$41, MATCH(C8, Customers!A$2:A$41, 0)) -> Yes
A9: ORD0008 | B9: 45504 | C9: CUST006 | D9: PROD012 | E9: 6 | F9: =INDEX(Customers!B3:B23, MATCH(C9, Customers!A3:A23, 0)) -> Jane Taylor | G9: =INDEX(Customers!C$1:C$21, MATCH(C9, Customers!A$1:A$21, 0)) -> egould@navarro.biz | H9: =INDEX(Customers!$G$1:$G$21, MATCH(C9,Customers!$A$1:$A$21,0)) -> Tuvalu | I9: =INDEX(Products!B$2:B$41, MATCH(D9, Products!A$2:A$41, 0)) -> Americano | J9: =INDEX(Products!C$2:C$41, MATCH(D9, Products!A$2:A$41, 0)) -> Medium | K9: =INDEX(Products!D$2:D$41, MATCH(D9, Products!A$2:A$41, 0)) -> Large | L9: =INDEX(Products!E$2:E$41, MATCH(D9, Products!A$2:A$41, 0)) -> 4.82 | M9: =L9*E9 -> 28.92 | N9: =INDEX(Customers!I$2:I$41, MATCH(C9, Customers!A$2:A$41, 0)) -> No
A10: ORD0009 | B10: 45663 | C10: CUST019 | D10: PROD004 | E10: 2 | F10: =INDEX(Customers!B4:B24, MATCH(C10, Customers!A4:A24, 0)) -> Angie Tucker | G10: =INDEX(Customers!C$1:C$21, MATCH(C10, Customers!A$1:A$21, 0)) -> tholland@turner.info | H10: =INDEX(Customers!$G$1:$G$21, MATCH(C10,Customers!$A$1:$A$21,0)) -> Namibia | I10: =INDEX(Products!B$2:B$41, MATCH(D10, Products!A$2:A$41, 0)) -> Latte | J10: =INDEX(Products!C$2:C$41, MATCH(D10, Products!A$2:A$41, 0)) -> Dark | K10: =INDEX(Products!D$2:D$41, MATCH(D10, Products!A$2:A$41, 0)) -> Medium | L10: =INDEX(Products!E$2:E$41, MATCH(D10, Products!A$2:A$41, 0)) -> 3.74 | M10: =L10*E10 -> 7.48 | N10: =INDEX(Customers!I$2:I$41, MATCH(C10, Customers!A$2:A$41, 0)) -> Yes
A11: ORD0010 | B11: 45572 | C11: CUST020 | D11: PROD016 | E11: 10 | F11: =INDEX(Customers!B5:B25, MATCH(C11, Customers!A5:A25, 0)) -> Natalie Cox | G11: =INDEX(Customers!C$1:C$21, MATCH(C11, Customers!A$1:A$21, 0)) -> cervantesgabriela@morgan.net | H11: =INDEX(Customers!$G$1:$G$21, MATCH(C11,Customers!$A$1:$A$21,0)) -> Northern Mariana Islands | I11: =INDEX(Products!B$2:B$41, MATCH(D11, Products!A$2:A$41, 0)) -> Mocha | J11: =INDEX(Products!C$2:C$41, MATCH(D11, Products!A$2:A$41, 0)) -> Medium | K11: =INDEX(Products!D$2:D$41, MATCH(D11, Products!A$2:A$41, 0)) -> Large | L11: =INDEX(Products!E$2:E$41, MATCH(D11, Products!A$2:A$41, 0)) -> 4.74 | M11: =L11*E11 -> 47.4 | N11: =INDEX(Customers!I$2:I$41, MATCH(C11, Customers!A$2:A$41, 0)) -> No | O11: Column1
A12: ORD0011 | B12: 45517 | C12: CUST018 | D12: PROD010 | E12: 4 | F12: =INDEX(Customers!B6:B26, MATCH(C12, Customers!A6:A26, 0)) -> Jeffrey Moore | G12: =INDEX(Customers!C$1:C$21, MATCH(C12, Customers!A$1:A$21, 0)) -> jessica31@sanchez-young.com | H12: =INDEX(Customers!$G$1:$G$21, MATCH(C12,Customers!$A$1:$A$21,0)) -> Slovenia | I12: =INDEX(Products!B$2:B$41, MATCH(D12, Products!A$2:A$41, 0)) -> Flat White | J12: =INDEX(Products!C$2:C$41, MATCH(D12, Products!A$2:A$41, 0)) -> Dark | K12: =INDEX(Products!D$2:D$41, MATCH(D12, Products!A$2:A$41, 0)) -> Large | L12: =INDEX(Products!E$2:E$41, MATCH(D12, Products!A$2:A$41, 0)) -> 5.29 | M12: =L12*E12 -> 21.16 | N12: =INDEX(Customers!I$2:I$41, MATCH(C12, Customers!A$2:A$41, 0)) -> No
A13: ORD0012 | B13: 45518 | C13: CUST005 | D13: PROD014 | E13: 3 | F13: =INDEX(Customers!B1:$B$21, MATCH(C7,Customers!A1:$A$21,0)) -> Teresa Collins | G13: =INDEX(Customers!C$1:C$21, MATCH(C13, Customers!A$1:A$21, 0)) -> hestercharles@jackson-hicks.com | H13: =INDEX(Customers!$G$1:$G$21, MATCH(C13,Customers!$A$1:$A$21,0)) -> Cook Islands | I13: =INDEX(Products!B$2:B$41, MATCH(D13, Products!A$2:A$41, 0)) -> Espresso | J13: =INDEX(Products!C$2:C$41, MATCH(D13, Products!A$2:A$41, 0)) -> Light | K13: =INDEX(Products!D$2:D$41, MATCH(D13, Products!A$2:A$41, 0)) -> Small | L13: =INDEX(Products!E$2:E$41, MATCH(D13, Products!A$2:A$41, 0)) -> 3.13 | M13: =L13*E13 -> 9.39 | N13: =INDEX(Customers!I$2:I$41, MATCH(C13, Customers!A$2:A$41, 0)) -> Yes
A14: ORD0013 | B14: 45577 | C14: CUST016 | D14: PROD006 | E14: 1 | F14: =INDEX(Customers!B8:B28, MATCH(C14, Customers!A8:A28, 0)) -> Megan Rice | G14: =INDEX(Customers!C$1:C$21, MATCH(C14, Customers!A$1:A$21, 0)) -> bakerjuan@hotmail.com | H14: =INDEX(Customers!$G$1:$G$21, MATCH(C14,Customers!$A$1:$A$21,0)) -> Moldova | I14: =INDEX(Products!B$2:B$41, MATCH(D14, Products!A$2:A$41, 0)) -> Americano | J14: =INDEX(Products!C$2:C$41, MATCH(D14, Products!A$2:A$41, 0)) -> Light | K14: =INDEX(Products!D$2:D$41, MATCH(D14, Products!A$2:A$41, 0)) -> Large | L14: =INDEX(Products!E$2:E$41, MATCH(D14, Products!A$2:A$41, 0)) -> 5.4 | M14: =L14*E14 -> 5.4 | N14: =INDEX(Customers!I$2:I$41, MATCH(C14, Customers!A$2:A$41, 0)) -> Yes
A15: ORD0014 | B15: 45642 | C15: CUST005 | D15: PROD003 | E15: 6 | F15: =INDEX(Customers!$B$1:$B$21, MATCH(C15,Customers!$A$1:$A$21,0)) -> Joshua Oneal | G15: =INDEX(Customers!C$1:C$21, MATCH(C15, Customers!A$1:A$21, 0)) -> hestercharles@jackson-hicks.com | H15: =INDEX(Customers!$G$1:$G$21, MATCH(C15,Customers!$A$1:$A$21,0)) -> Cook Islands | I15: =INDEX(Products!B$2:B$41, MATCH(D15, Products!A$2:A$41, 0)) -> Latte | J15: =INDEX(Products!C$2:C$41, MATCH(D15, Products!A$2:A$41, 0)) -> Dark | K15: =INDEX(Products!D$2:D$41, MATCH(D15, Products!A$2:A$41, 0)) -> Large | L15: =INDEX(Products!E$2:E$41, MATCH(D15, Products!A$2:A$41, 0)) -> 5 | M15: =L15*E15 -> 30 | N15: =INDEX(Customers!I$2:I$41, MATCH(C15, Customers!A$2:A$41, 0)) -> Yes
A16: ORD0015 | B16: 45691 | C16: CUST014 | D16: PROD018 | E16: 6 | F16: =INDEX(Customers!B10:B30, MATCH(C16, Customers!A10:A30, 0)) -> Timothy Anderson | G16: =INDEX(Customers!C$1:C$21, MATCH(C16, Customers!A$1:A$21, 0)) -> ucunningham@webb.com | H16: =INDEX(Customers!$G$1:$G$21, MATCH(C16,Customers!$A$1:$A$21,0)) -> Montenegro | I16: =INDEX(Products!B$2:B$41, MATCH(D16, Products!A$2:A$41, 0)) -> Mocha | J16: =INDEX(Products!C$2:C$41, MATCH(D16, Products!A$2:A$41, 0)) -> Dark | K16: =INDEX(Products!D$2:D$41, MATCH(D16, Products!A$2:A$41, 0)) -> Small | L16: =INDEX(Products!E$2:E$41, MATCH(D16, Products!A$2:A$41, 0)) -> 2.65 | M16: =L16*E16 -> 15.9 | N16: =INDEX(Customers!I$2:I$41, MATCH(C16, Customers!A$2:A$41, 0)) -> No
A17: ORD0016 | B17: 45485 | C17: CUST020 | D17: PROD004 | E17: 8 | F17: =INDEX(Customers!B11:B31, MATCH(C17, Customers!A11:A31, 0)) -> Natalie Cox | G17: =INDEX(Customers!C$1:C$21, MATCH(C17, Customers!A$1:A$21, 0)) -> cervantesgabriela@morgan.net | H17: =INDEX(Customers!$G$1:$G$21, MATCH(C17,Customers!$A$1:$A$21,0)) -> Northern Mariana Islands | I17: =INDEX(Products!B$2:B$41, MATCH(D17, Products!A$2:A$41, 0)) -> Latte | J17: =INDEX(Products!C$2:C$41, MATCH(D17, Products!A$2:A$41, 0)) -> Dark | K17: =INDEX(Products!D$2:D$41, MATCH(D17, Products!A$2:A$41, 0)) -> Medium | L17: =INDEX(Products!E$2:E$41, MATCH(D17, Products!A$2:A$41, 0)) -> 3.74 | M17: =L17*E17 -> 29.92 | N17: =INDEX(Customers!I$2:I$41, MATCH(C17, Customers!A$2:A$41, 0)) -> No
A18: ORD0017 | B18: 45692 | C18: CUST014 | D18: PROD011 | E18: 8 | F18: =INDEX(Customers!B12:B32, MATCH(C18, Customers!A12:A32, 0)) -> Timothy Anderson | G18: =INDEX(Customers!C$1:C$21, MATCH(C18, Customers!A$1:A$21, 0)) -> ucunningham@webb.com | H18: =INDEX(Customers!$G$1:$G$21, MATCH(C18,Customers!$A$1:$A$21,0)) -> Montenegro | I18: =INDEX(Products!B$2:B$41, MATCH(D18, Products!A$2:A$41, 0)) -> Cappuccino | J18: =INDEX(Products!C$2:C$41, MATCH(D18, Products!A$2:A$41, 0)) -> Medium | K18: =INDEX(Products!D$2:D$41, MATCH(D18, Products!A$2:A$41, 0)) -> Medium | L18: =INDEX(Products!E$2:E$41, MATCH(D18, Products!A$2:A$41, 0)) -> 4.42 | M18: =L18*E18 -> 35.36 | N18: =INDEX(Customers!I$2:I$41, MATCH(C18, Customers!A$2:A$41, 0)) -> No
A19: ORD0018 | B19: 45533 | C19: CUST018 | D19: PROD014 | E19: 6 | F19: =INDEX(Customers!B13:B33, MATCH(C19, Customers!A13:A33, 0)) -> Jeffrey Moore | G19: =INDEX(Customers!C$1:C$21, MATCH(C19, Customers!A$1:A$21, 0)) -> jessica31@sanchez-young.com | H19: =INDEX(Customers!$G$1:$G$21, MATCH(C19,Customers!$A$1:$A$21,0)) -> Slovenia | I19: =INDEX(Products!B$2:B$41, MATCH(D19, Products!A$2:A$41, 0)) -> Espresso | J19: =INDEX(Products!C$2:C$41, MATCH(D19, Products!A$2:A$41, 0)) -> Light | K19: =INDEX(Products!D$2:D$41, MATCH(D19, Products!A$2:A$41, 0)) -> Small | L19: =INDEX(Products!E$2:E$41, MATCH(D19, Products!A$2:A$41, 0)) -> 3.13 | M19: =L19*E19 -> 18.78 | N19: =INDEX(Customers!I$2:I$41, MATCH(C19, Customers!A$2:A$41, 0)) -> No
A20: ORD0019 | B20: 45499 | C20: CUST015 | D20: PROD020 | E20: 2 | F20: =INDEX(Customers!B14:B34, MATCH(C20, Customers!A14:A34, 0)) -> Teresa Collins | G20: =INDEX(Customers!C$1:C$21, MATCH(C20, Customers!A$1:A$21, 0)) -> carsonkenneth@hotmail.com | H20: =INDEX(Customers!$G$1:$G$21, MATCH(C20,Customers!$A$1:$A$21,0)) -> Anguilla | I20: =INDEX(Products!B$2:B$41, MATCH(D20, Products!A$2:A$41, 0)) -> Latte | J20: =INDEX(Products!C$2:C$41, MATCH(D20, Products!A$2:A$41, 0)) -> Light | K20: =INDEX(Products!D$2:D$41, MATCH(D20, Products!A$2:A$41, 0)) -> Small | L20: =INDEX(Products!E$2:E$41, MATCH(D20, Products!A$2:A$41, 0)) -> 3.38 | M20: =L20*E20 -> 6.76 | N20: =INDEX(Customers!I$2:I$41, MATCH(C20, Customers!A$2:A$41, 0)) -> Yes
A21: ORD0020 | B21: 45687 | C21: CUST014 | D21: PROD005 | E21: 5 | F21: =INDEX(Customers!B15:B35, MATCH(C21, Customers!A15:A35, 0)) -> Timothy Anderson | G21: =INDEX(Customers!C$1:C$21, MATCH(C21, Customers!A$1:A$21, 0)) -> ucunningham@webb.com | H21: =INDEX(Customers!$G$1:$G$21, MATCH(C21,Customers!$A$1:$A$21,0)) -> Montenegro | I21: =INDEX(Products!B$2:B$41, MATCH(D21, Products!A$2:A$41, 0)) -> Espresso | J21: =INDEX(Products!C$2:C$41, MATCH(D21, Products!A$2:A$41, 0)) -> Medium | K21: =INDEX(Products!D$2:D$41, MATCH(D21, Products!A$2:A$41, 0)) -> Medium | L21: =INDEX(Products!E$2:E$41, MATCH(D21, Products!A$2:A$41, 0)) -> 4.33 | M21: =L21*E21 -> 21.65 | N21: =INDEX(Customers!I$2:I$41, MATCH(C21, Customers!A$2:A$41, 0)) -> No
A22: ORD0021 | B22: 45503 | C22: CUST020 | D22: PROD009 | E22: 8 | F22: =INDEX(Customers!B16:B36, MATCH(C22, Customers!A16:A36, 0)) -> Natalie Cox | G22: =INDEX(Customers!C$1:C$21, MATCH(C22, Customers!A$1:A$21, 0)) -> cervantesgabriela@morgan.net | H22: =INDEX(Customers!$G$1:$G$21, MATCH(C22,Customers!$A$1:$A$21,0)) -> Northern Mariana Islands | I22: =INDEX(Products!B$2:B$41, MATCH(D22, Products!A$2:A$41, 0)) -> Flat White | J22: =INDEX(Products!C$2:C$41, MATCH(D22, Products!A$2:A$41, 0)) -> Dark | K22: =INDEX(Products!D$2:D$41, MATCH(D22, Products!A$2:A$41, 0)) -> Small | L22: =INDEX(Products!E$2:E$41, MATCH(D22, Products!A$2:A$41, 0)) -> 3.11 | M22: =L22*E22 -> 24.88 | N22: =INDEX(Customers!I$2:I$41, MATCH(C22, Customers!A$2:A$41, 0)) -> No
A23: ORD0022 | B23: 45452 | C23: CUST003 | D23: PROD002 | E23: 8 | F23: =INDEX(Customers!B$1:B$21, MATCH(C23, Customers!A$1:A$21, 0)) -> Carolyn Howard | G23: =INDEX(Customers!C$1:C$21, MATCH(C23, Customers!A$1:A$21, 0)) -> scott42@thompson-friedman.org | H23: =INDEX(Customers!$G$1:$G$21, MATCH(C23,Customers!$A$1:$A$21,0)) -> Montserrat | I23: =INDEX(Products!B$2:B$41, MATCH(D23, Products!A$2:A$41, 0)) -> Mocha | J23: =INDEX(Products!C$2:C$41, MATCH(D23, Products!A$2:A$41, 0)) -> Light | K23: =INDEX(Products!D$2:D$41, MATCH(D23, Products!A$2:A$41, 0)) -> Large | L23: =INDEX(Products!E$2:E$41, MATCH(D23, Products!A$2:A$41, 0)) -> 4.8 | M23: =L23*E23 -> 38.4 | N23: =INDEX(Customers!I$2:I$41, MATCH(C23, Customers!A$2:A$41, 0)) -> Yes
A24: ORD0023 | B24: 45616 | C24: CUST019 | D24: PROD018 | E24: 5 | F24: =INDEX(Customers!B18:B38, MATCH(C24, Customers!A18:A38, 0)) -> Angie Tucker | G24: =INDEX(Customers!C$1:C$21, MATCH(C24, Customers!A$1:A$21, 0)) -> tholland@turner.info | H24: =INDEX(Customers!$G$1:$G$21, MATCH(C24,Customers!$A$1:$A$21,0)) -> Namibia | I24: =INDEX(Products!B$2:B$41, MATCH(D24, Products!A$2:A$41, 0)) -> Mocha | J24: =INDEX(Products!C$2:C$41, MATCH(D24, Products!A$2:A$41, 0)) -> Dark | K24: =INDEX(Products!D$2:D$41, MATCH(D24, Products!A$2:A$41, 0)) -> Small | L24: =INDEX(Products!E$2:E$41, MATCH(D24, Products!A$2:A$41, 0)) -> 2.65 | M24: =L24*E24 -> 13.25 | N24: =INDEX(Customers!I$2:I$41, MATCH(C24, Customers!A$2:A$41, 0)) -> Yes
A25: ORD0024 | B25: 45518 | C25: CUST001 | D25: PROD015 | E25: 6 | F25: =INDEX(Customers!$B$1:$B$21,MATCH(owner!C25,Customers!A1:A21,0)) -> Jennifer Rodriguez | G25: =INDEX(Customers!C$1:C$21, MATCH(C25, Customers!A$1:A$21, 0)) -> tiffany38@hernandez-palmer.com | H25: =INDEX(Customers!$G$1:$G$21, MATCH(C25,Customers!$A$1:$A$21,0)) -> Uruguay | I25: =INDEX(Products!B$2:B$41, MATCH(D25, Products!A$2:A$41, 0)) -> Americano | J25: =INDEX(Products!C$2:C$41, MATCH(D25, Products!A$2:A$41, 0)) -> Dark | K25: =INDEX(Products!D$2:D$41, MATCH(D25, Products!A$2:A$41, 0)) -> Medium | L25: =INDEX(Products!E$2:E$41, MATCH(D25, Products!A$2:A$41, 0)) -> 4.37 | M25: =L25*E25 -> 26.22 | N25: =INDEX(Customers!I$2:I$41, MATCH(C25, Customers!A$2:A$41, 0)) -> No
A26: ORD0025 | B26: 45463 | C26: CUST013 | D26: PROD016 | E26: 4 | F26: =INDEX(Customers!$B$1:$B$21,MATCH(owner!C26,Customers!A2:A22,0)) -> Billy Chan | G26: =INDEX(Customers!C$1:C$21, MATCH(C26, Customers!A$1:A$21, 0)) -> gregory16@murphy.com | H26: =INDEX(Customers!$G$1:$G$21, MATCH(C26,Customers!$A$1:$A$21,0)) -> Zambia | I26: =INDEX(Products!B$2:B$41, MATCH(D26, Products!A$2:A$41, 0)) -> Mocha | J26: =INDEX(Products!C$2:C$41, MATCH(D26, Products!A$2:A$41, 0)) -> Medium | K26: =INDEX(Products!D$2:D$41, MATCH(D26, Products!A$2:A$41, 0)) -> Large | L26: =INDEX(Products!E$2:E$41, MATCH(D26, Products!A$2:A$41, 0)) -> 4.74 | M26: =L26*E26 -> 18.96 | N26: =INDEX(Customers!I$2:I$41, MATCH(C26, Customers!A$2:A$41, 0)) -> Yes
A27: ORD0026 | B27: 45668 | C27: CUST010 | D27: PROD007 | E27: 6 | F27: =INDEX(Customers!$B$1:$B$21,MATCH(owner!C27,Customers!A3:A23,0)) -> Sarah Johnson | G27: =INDEX(Customers!C$1:C$21, MATCH(C27, Customers!A$1:A$21, 0)) -> rvillanueva@hotmail.com | H27: =INDEX(Customers!$G$1:$G$21, MATCH(C27,Customers!$A$1:$A$21,0)) -> Greenland | I27: =INDEX(Products!B$2:B$41, MATCH(D27, Products!A$2:A$41, 0)) -> Espresso | J27: =INDEX(Products!C$2:C$41, MATCH(D27, Products!A$2:A$41, 0)) -> Light | K27: =INDEX(Products!D$2:D$41, MATCH(D27, Products!A$2:A$41, 0)) -> Large | L27: =INDEX(Products!E$2:E$41, MATCH(D27, Products!A$2:A$41, 0)) -> 4.67 | M27: =L27*E27 -> 28.02 | N27: =INDEX(Customers!I$2:I$41, MATCH(C27, Customers!A$2:A$41, 0)) -> Yes
A28: ORD0027 | B28: 45709 | C28: CUST012 | D28: PROD012 | E28: 3 | F28: =INDEX(Customers!$B$1:$B$21,MATCH(owner!C28,Customers!A4:A24,0)) -> Ashley Guerrero | G28: =INDEX(Customers!C$1:C$21, MATCH(C28, Customers!A$1:A$21, 0)) -> jonathandavis@yahoo.com | H28: =INDEX(Customers!$G$1:$G$21, MATCH(C28,Customers!$A$1:$A$21,0)) -> Turks and Caicos Islands | I28: =INDEX(Products!B$2:B$41, MATCH(D28, Products!A$2:A$41, 0)) -> Americano | J28: =INDEX(Products!C$2:C$41, MATCH(D28, Products!A$2:A$41, 0)) -> Medium | K28: =INDEX(Products!D$2:D$41, MATCH(D28, Products!A$2:A$41, 0)) -> Large | L28: =INDEX(Products!E$2:E$41, MATCH(D28, Products!A$2:A$41, 0)) -> 4.82 | M28: =L28*E28 -> 14.46 | N28: =INDEX(Customers!I$2:I$41, MATCH(C28, Customers!A$2:A$41, 0)) -> No
A29: ORD0028 | B29: 45512 | C29: CUST014 | D29: PROD015 | E29: 1 | F29: =INDEX(Customers!$B$1:$B$21,MATCH(owner!C29,Customers!A5:A25,0)) -> Robin Johnson | G29: =INDEX(Customers!C$1:C$21, MATCH(C29, Customers!A$1:A$21, 0)) -> ucunningham@webb.com | H29: =INDEX(Customers!$G$1:$G$21, MATCH(C29,Customers!$A$1:$A$21,0)) -> Montenegro | I29: =INDEX(Products!B$2:B$41, MATCH(D29, Products!A$2:A$41, 0)) -> Americano | J29: =INDEX(Products!C$2:C$41, MATCH(D29, Products!A$2:A$41, 0)) -> Dark | K29: =INDEX(Products!D$2:D$41, MATCH(D29, Products!A$2:A$41, 0)) -> Medium | L29: =INDEX(Products!E$2:E$41, MATCH(D29, Products!A$2:A$41, 0)) -> 4.37 | M29: =L29*E29 -> 4.37 | N29: =INDEX(Customers!I$2:I$41, MATCH(C29, Customers!A$2:A$41, 0)) -> No
A30: ORD0029 | B30: 45534 | C30: CUST009 | D30: PROD015 | E30: 2 | F30: =INDEX(Customers!$B$1:$B$21,MATCH(owner!C30,Customers!A6:A26,0)) -> Jessica Young | G30: =INDEX(Customers!C$1:C$21, MATCH(C30, Customers!A$1:A$21, 0)) -> clementscole@stewart.com | H30: =INDEX(Customers!$G$1:$G$21, MATCH(C30,Customers!$A$1:$A$21,0)) -> Congo | I30: =INDEX(Products!B$2:B$41, MATCH(D30, Products!A$2:A$41, 0)) -> Americano | J30: =INDEX(Products!C$2:C$41, MATCH(D30, Products!A$2:A$41, 0)) -> Dark | K30: =INDEX(Products!D$2:D$41, MATCH(D30, Products!A$2:A$41, 0)) -> Medium | L30: =INDEX(Products!E$2:E$41, MATCH(D30, Products!A$2:A$41, 0)) -> 4.37 | M30: =L30*E30 -> 8.74 | N30: =INDEX(Customers!I$2:I$41, MATCH(C30, Customers!A$2:A$41, 0)) -> No
A31: ORD0030 | B31: 45663 | C31: CUST016 | D31: PROD016 | E31: 6 | F31: =INDEX(Customers!$B$1:$B$21,MATCH(owner!C31,Customers!A7:A27,0)) -> Robin Johnson | G31: =INDEX(Customers!C$1:C$21, MATCH(C31, Customers!A$1:A$21, 0)) -> bakerjuan@hotmail.com | H31: =INDEX(Customers!$G$1:$G$21, MATCH(C31,Customers!$A$1:$A$21,0)) -> Moldova | I31: =INDEX(Products!B$2:B$41, MATCH(D31, Products!A$2:A$41, 0)) -> Mocha | J31: =INDEX(Products!C$2:C$41, MATCH(D31, Products!A$2:A$41, 0)) -> Medium | K31: =INDEX(Products!D$2:D$41, MATCH(D31, Products!A$2:A$41, 0)) -> Large | L31: =INDEX(Products!E$2:E$41, MATCH(D31, Products!A$2:A$41, 0)) -> 4.74 | M31: =L31*E31 -> 28.44 | N31: =INDEX(Customers!I$2:I$41, MATCH(C31, Customers!A$2:A$41, 0)) -> Yes
A32: ORD0031 | B32: 45758 | C32: CUST014 | D32: PROD011 | E32: 8 | F32: =INDEX(Customers!$B$1:$B$21,MATCH(owner!C32,Customers!A8:A28,0)) -> Dustin Levy | G32: =INDEX(Customers!C$1:C$21, MATCH(C32, Customers!A$1:A$21, 0)) -> ucunningham@webb.com | H32: =INDEX(Customers!$G$1:$G$21, MATCH(C32,Customers!$A$1:$A$21,0)) -> Montenegro | I32: =INDEX(Products!B$2:B$41, MATCH(D32, Products!A$2:A$41, 0)) -> Cappuccino | J32: =INDEX(Products!C$2:C$41, MATCH(D32, Products!A$2:A$41, 0)) -> Medium | K32: =INDEX(Products!D$2:D$41, MATCH(D32, Products!A$2:A$41, 0)) -> Medium | L32: =INDEX(Products!E$2:E$41, MATCH(D32, Products!A$2:A$41, 0)) -> 4.42 | M32: =L32*E32 -> 35.36 | N32: =INDEX(Customers!I$2:I$41, MATCH(C32, Customers!A$2:A$41, 0)) -> No
A33: ORD0032 | B33: 45713 | C33: CUST013 | D33: PROD001 | E33: 9 | F33: =INDEX(Customers!$B$1:$B$21,MATCH(owner!C33,Customers!A9:A29,0)) -> Joshua Oneal | G33: =INDEX(Customers!C$1:C$21, MATCH(C33, Customers!A$1:A$21, 0)) -> gregory16@murphy.com | H33: =INDEX(Customers!$G$1:$G$21, MATCH(C33,Customers!$A$1:$A$21,0)) -> Zambia | I33: =INDEX(Products!B$2:B$41, MATCH(D33, Products!A$2:A$41, 0)) -> Flat White | J33: =INDEX(Products!C$2:C$41, MATCH(D33, Products!A$2:A$41, 0)) -> Light | K33: =INDEX(Products!D$2:D$41, MATCH(D33, Products!A$2:A$41, 0)) -> Small | L33: =INDEX(Products!E$2:E$41, MATCH(D33, Products!A$2:A$41, 0)) -> 3.24 | M33: =L33*E33 -> 29.16 | N33: =INDEX(Customers!I$2:I$41, MATCH(C33, Customers!A$2:A$41, 0)) -> Yes
A34: ORD0033 | B34: 45662 | C34: CUST018 | D34: PROD002 | E34: 3 | F34: =INDEX(Customers!$B$1:$B$21,MATCH(owner!C34,Customers!A10:A30,0)) -> Ashley Guerrero | G34: =INDEX(Customers!C$1:C$21, MATCH(C34, Customers!A$1:A$21, 0)) -> jessica31@sanchez-young.com | H34: =INDEX(Customers!$G$1:$G$21, MATCH(C34,Customers!$A$1:$A$21,0)) -> Slovenia | I34: =INDEX(Products!B$2:B$41, MATCH(D34, Products!A$2:A$41, 0)) -> Mocha | J34: =INDEX(Products!C$2:C$41, MATCH(D34, Products!A$2:A$41, 0)) -> Light | K34: =INDEX(Products!D$2:D$41, MATCH(D34, Products!A$2:A$41, 0)) -> Large | L34: =INDEX(Products!E$2:E$41, MATCH(D34, Products!A$2:A$41, 0)) -> 4.8 | M34: =L34*E34 -> 14.4 | N34: =INDEX(Customers!I$2:I$41, MATCH(C34, Customers!A$2:A$41, 0)) -> No
A35: ORD0034 | B35: 45778 | C35: CUST005 | D35: PROD005 | E35: 9 | F35: =INDEX(Customers!B$1:B$21, MATCH(C35, Customers!A$1:A$21, 0)) -> Joshua Oneal | G35: =INDEX(Customers!C$1:C$21, MATCH(C35, Customers!A$1:A$21, 0)) -> hestercharles@jackson-hicks.com | H35: =INDEX(Customers!$G$1:$G$21, MATCH(C35,Customers!$A$1:$A$21,0)) -> Cook Islands | I35: =INDEX(Products!B$2:B$41, MATCH(D35, Products!A$2:A$41, 0)) -> Espresso | J35: =INDEX(Products!C$2:C$41, MATCH(D35, Products!A$2:A$41, 0)) -> Medium | K35: =INDEX(Products!D$2:D$41, MATCH(D35, Products!A$2:A$41, 0)) -> Medium | L35: =INDEX(Products!E$2:E$41, MATCH(D35, Products!A$2:A$41, 0)) -> 4.33 | M35: =L35*E35 -> 38.97 | N35: =INDEX(Customers!I$2:I$41, MATCH(C35, Customers!A$2:A$41, 0)) -> Yes
A36: ORD0035 | B36: 45689 | C36: CUST001 | D36: PROD013 | E36: 7 | F36: =INDEX(Customers!B$1:B$21, MATCH(C36, Customers!A$1:A$21, 0)) -> Jennifer Rodriguez | G36: =INDEX(Customers!C$1:C$21, MATCH(C36, Customers!A$1:A$21, 0)) -> tiffany38@hernandez-palmer.com | H36: =INDEX(Customers!$G$1:$G$21, MATCH(C36,Customers!$A$1:$A$21,0)) -> Uruguay | I36: =INDEX(Products!B$2:B$41, MATCH(D36, Products!A$2:A$41, 0)) -> Mocha | J36: =INDEX(Products!C$2:C$41, MATCH(D36, Products!A$2:A$41, 0)) -> Medium | K36: =INDEX(Products!D$2:D$41, MATCH(D36, Products!A$2:A$41, 0)) -> Large | L36: =INDEX(Products!E$2:E$41, MATCH(D36, Products!A$2:A$41, 0)) -> 5.5 | M36: =L36*E36 -> 38.5 | N36: =INDEX(Customers!I$2:I$41, MATCH(C36, Customers!A$2:A$41, 0)) -> No
A37: ORD0036 | B37: 45728 | C37: CUST020 | D37: PROD012 | E37: 10 | F37: =INDEX(Customers!B$1:B$21, MATCH(C37, Customers!A$1:A$21, 0)) -> Natalie Cox | G37: =INDEX(Customers!C$1:C$21, MATCH(C37, Customers!A$1:A$21, 0)) -> cervantesgabriela@morgan.net | H37: =INDEX(Customers!$G$1:$G$21, MATCH(C37,Customers!$A$1:$A$21,0)) -> Northern Mariana Islands | I37: =INDEX(Products!B$2:B$41, MATCH(D37, Products!A$2:A$41, 0)) -> Americano | J37: =INDEX(Products!C$2:C$41, MATCH(D37, Products!A$2:A$41, 0)) -> Medium | K37: =INDEX(Products!D$2:D$41, MATCH(D37, Products!A$2:A$41, 0)) -> Large | L37: =INDEX(Products!E$2:E$41, MATCH(D37, Products!A$2:A$41, 0)) -> 4.82 | M37: =L37*E37 -> 48.2 | N37: =INDEX(Customers!I$2:I$41, MATCH(C37, Customers!A$2:A$41, 0)) -> No
A38: ORD0037 | B38: 45599 | C38: CUST014 | D38: PROD003 | E38: 9 | F38: =INDEX(Customers!B$1:B$21, MATCH(C38, Customers!A$1:A$21, 0)) -> Timothy Anderson | G38: =INDEX(Customers!C$1:C$21, MATCH(C38, Customers!A$1:A$21, 0)) -> ucunningham@webb.com | H38: =INDEX(Customers!$G$1:$G$21, MATCH(C38,Customers!$A$1:$A$21,0)) -> Montenegro | I38: =INDEX(Products!B$2:B$41, MATCH(D38, Products!A$2:A$41, 0)) -> Latte | J38: =INDEX(Products!C$2:C$41, MATCH(D38, Products!A$2:A$41, 0)) -> Dark | K38: =INDEX(Products!D$2:D$41, MATCH(D38, Products!A$2:A$41, 0)) -> Large | L38: =INDEX(Products!E$2:E$41, MATCH(D38, Products!A$2:A$41, 0)) -> 5 | M38: =L38*E38 -> 45 | N38: =INDEX(Customers!I$2:I$41, MATCH(C38, Customers!A$2:A$41, 0)) -> No
A39: ORD0038 | B39: 45727 | C39: CUST009 | D39: PROD013 | E39: 1 | F39: =INDEX(Customers!B$1:B$21, MATCH(C39, Customers!A$1:A$21, 0)) -> Ashley Guerrero | G39: =INDEX(Customers!C$1:C$21, MATCH(C39, Customers!A$1:A$21, 0)) -> clementscole@stewart.com | H39: =INDEX(Customers!$G$1:$G$21, MATCH(C39,Customers!$A$1:$A$21,0)) -> Congo | I39: =INDEX(Products!B$2:B$41, MATCH(D39, Products!A$2:A$41, 0)) -> Mocha | J39: =INDEX(Products!C$2:C$41, MATCH(D39, Products!A$2:A$41, 0)) -> Medium | K39: =INDEX(Products!D$2:D$41, MATCH(D39, Products!A$2:A$41, 0)) -> Large | L39: =INDEX(Products!E$2:E$41, MATCH(D39, Products!A$2:A$41, 0)) -> 5.5 | M39: =L39*E39 -> 5.5 | N39: =INDEX(Customers!I$2:I$41, MATCH(C39, Customers!A$2:A$41, 0)) -> No
A40: ORD0039 | B40: 45679 | C40: CUST009 | D40: PROD020 | E40: 7 | F40: =INDEX(Customers!B$1:B$21, MATCH(C40, Customers!A$1:A$21, 0)) -> Ashley Guerrero | G40: =INDEX(Customers!C$1:C$21, MATCH(C40, Customers!A$1:A$21, 0)) -> clementscole@stewart.com | H40: =INDEX(Customers!$G$1:$G$21, MATCH(C40,Customers!$A$1:$A$21,0)) -> Congo | I40: =INDEX(Products!B$2:B$41, MATCH(D40, Products!A$2:A$41, 0)) -> Latte | J40: =INDEX(Products!C$2:C$41, MATCH(D40, Products!A$2:A$41, 0)) -> Light | K40: =INDEX(Products!D$2:D$41, MATCH(D40, Products!A$2:A$41, 0)) -> Small | L40: =INDEX(Products!E$2:E$41, MATCH(D40, Products!A$2:A$41, 0)) -> 3.38 | M40: =L40*E40 -> 23.66 | N40: =INDEX(Customers!I$2:I$41, MATCH(C40, Customers!A$2:A$41, 0)) -> No
...

Sheet Products
A1: Product ID | B1: Coffee Type | C1: Roast Type | D1: Size | E1: Unit Price | F1: Price per 100g | G1: Profit
A2: PROD001 | B2: Flat White | C2: Light | D2: Small | E2: 3.24 | F2: 3.02 | G2: 1.13
A3: PROD002 | B3: Mocha | C3: Light | D3: Large | E3: 4.8 | F3: 5.04 | G3: 0.98
A4: PROD003 | B4: Latte | C4: Dark | D4: Large | E4: 5 | F4: 4.92 | G4: 1.87
A5: PROD004 | B5: Latte | C5: Dark | D5: Medium | E5: 3.74 | F5: 3.74 | G5: 0.82
A6: PROD005 | B6: Espresso | C6: Medium | D6: Medium | E6: 4.33 | F6: 4.59 | G6: 1.71
A7: PROD006 | B7: Americano | C7: Light | D7: Large | E7: 5.4 | F7: 5.44 | G7: 1.29
A8: PROD007 | B8: Espresso | C8: Light | D8: Large | E8: 4.67 | F8: 4.53 | G8: 1.03
A9: PROD008 | B9: Cappuccino | C9: Medium | D9: Large | E9: 4.92 | F9: 5.42 | G9: 1.67
A10: PROD009 | B10: Flat White | C10: Dark | D10: Small | E10: 3.11 | F10: 2.95 | G10: 0.86
A11: PROD010 | B11: Flat White | C11: Dark | D11: Large | E11: 5.29 | F11: 4.85 | G11: 1.93
A12: PROD011 | B12: Cappuccino | C12: Medium | D12: Medium | E12: 4.42 | F12: 4.93 | G12: 1.07
A13: PROD012 | B13: Americano | C13: Medium | D13: Large | E13: 4.82 | F13: 5.15 | G13: 1.22
... A41: PROD040 | B41: Latte | C41: Medium | D41: Small | E41: 3.39 | F41: 3.34 | G41: 0.82
